Workbook
Name Slicer_CITY: #N/A
Name Slicer_TYPE_CNTRL: #N/A
Name Slicer_TYPE_HOSP: #N/A

Sheet Append1
A1: FAC_NO | B1: FAC_NAME | C1: YEAR_QTR | D1: BEG_DATE | E1: END_DATE | F1: OP_STATUS | G1: COUNTY_NAME | H1: HSA | I1: HFPA | J1: TYPE_CNTRL | K1: TYPE_HOSP | L1: TEACH_RURL | M1: PHONE | N1: ADDRESS | O1: CITY | P1: ZIP_CODE | Q1: CEO | R1: LIC_BEDS | S1: AVL_BEDS | T1: STF_BEDS | U1: DIS_MCAR | V1: DIS_MCAR_MC | W1: DIS_MCAL | X1: DIS_MCAL_MC | Y1: DIS_CNTY | Z1: DIS_CNTY_MC | AA1: DIS_THRD | AB1: DIS_THRD_MC | AC1: DIS_INDGNT | AD1: DIS_OTH | AE1: DIS_TOT | AF1: DIS_LTC | AG1: DAY_MCAR | AH1: DAY_MCAR_MC | AI1: DAY_MCAL | AJ1: DAY_MCAL_MC | AK1: DAY_CNTY | AL1: DAY_CNTY_MC | AM1: DAY_THRD | AN1: DAY_THRD_MC | AO1: DAY_INDGNT | AP1: DAY_OTH | AQ1: DAY_TOT | AR1: DAY_LTC | AS1: Patient Days | AT1: VIS_MCAR | AU1: VIS_MCAR_MC | AV1: VIS_MCAL | AW1: VIS_MCAL_MC | AX1: VIS_CNTY | AY1: VIS_CNTY_MC | AZ1: VIS_THRD | BA1: VIS_THRD_MC | BB1: VIS_INDGNT | BC1: VIS_OTH | BD1: VIS_TOT | BE1: GRIP_MCAR | BF1: GRIP_MCAR_MC | BG1: GRIP_MCAL | BH1: GRIP_MCAL_MC | BI1: GRIP_CNTY | BJ1: GRIP_CNTY_MC | BK1: GRIP_THRD | BL1: GRIP_THRD_MC | BM1: GRIP_INDGNT | BN1: GRIP_OTH | BO1: GRIP_TOT | BP1: GROP_MCAR | BQ1: GROP_MCAR_MC | BR1: GROP_MCAL | BS1: GROP_MCAL_MC | BT1: GROP_CNTY | BU1: GROP_CNTY_MC | BV1: GROP_THRD | BW1: GROP_THRD_MC | BX1: GROP_INDGNT | BY1: GROP_OTH | BZ1: GROP_TOT | CA1: BAD_DEBT | CB1: CADJ_MCAR | CC1: CADJ_MCAR_MC | CD1: CADJ_MCAL | CE1: CADJ_MCAL_MC | CF1: DISP_855 | CG1: CADJ_CNTY | CH1: CADJ_CNTY_MC | CI1: CADJ_THRD | CJ1: CADJ_THRD_MC | CK1: CHAR_HB | CL1: CHAR_OTH | CM1: SUB_INDGNT | CN1: TCH_ALLOW | CO1: TCH_SUPP | CP1: DED_OTH | CQ1: DED_TOT | CR1: CAP_MCAR | CS1: CAP_MCAL | CT1: CAP_CNTY | CU1: CAP_THRD | CV1: CAP_TOT | CW1: NET_MCAR | CX1: NET_MCAR_MC | CY1: NET_MCAL | CZ1: NET_MCAL_MC | DA1: NET_CNTY | DB1: NET_CNTY_MC | DC1: NET_THRD | DD1: NET_THRD_MC | DE1: NET_INDGNT | DF1: NET_OTH | DG1: NET_TOT | DH1: OTH_OP_REV | DI1: TOT_OP_EXP | DJ1: PHY_COMP | DK1: NONOP_REV | DL1: DIS_PIPS | DM1: DAY_PIPS | DN1: EXP_PIPS | DO1: EXP_POPS | DP1: CAP_EXP | DQ1: FIX_ASSETS | DR1: DISP_TRNFR | DS1: DIS_TOT_CC | DT1: PAT_DAY_TOT_CC | DU1: TOT_OUT_VIS_CC | DV1: GROS_INPAT_REV_CC | DW1: GROS_OUTPAT_REV_CC | DX1: CONTR_ADJ_CC | DY1: OTHR_DEDUCT_CC | DZ1: CAP_PREM_REV_CC | EA1: NET_PAT_REV_CC | EB1: QA_FEES | EC1: QA_SUPPL_PAY | ED1: MNGD_CARE_QA_PAY
A2: 106150788 | B2: ADVENTIST HEALTH BAKERSFIELD | C2: 20174 | D2: 43009 | E2: 43100 | F2: Open | G2: Kern | H2: 9 | I2: 617 | J2: Non Profit Corp. | K2: Comparable | M2: 661-395-3000 | N2: 2615 CHESTER AVENUE | O2: BAKERSFIELD | P2: 93301 | Q2: SHARLET BRIGGS | R2: 254 | S2: 254 | T2: 185 | U2: 887 | V2: 765 | W2: 199 | X2: 1046 | Y2: 0 | Z2: 0 | AA2: 198 | AB2: 1170 | AC2: 0 | AD2: 70 | AE2: 4335 | AF2: 0 | AG2: 4003 | AH2: 3050 | AI2: 761 | AJ2: 3872 | AK2: 0 | AL2: 0 | AM2: 914 | AN2: 3747 | AO2: 0 | AP2: 267 | AQ2: 16614 | AR2: 0 | AS2: =Append1[[#This Row],[DAY_MCAR]]+Append1[[#This Row],[DAY_MCAR_MC]]+Append1[[#This Row],[DAY_MCAL]]+Append1[[#This Row],[DAY_MCAL_MC]]+Append1[[#This Row],[DAY_CNTY]]+Append1[[#This Row],[DAY_CNTY_MC]]+Append1[[#This Row],[DAY_THRD]]+Append1[[#This Row],[DAY_THRD_MC]]+Append1[[#This Row],[DAY_INDGNT]]+Append1[[#This Row],[DAY_OTH]]+Append1[[#This Row],[DAY_TOT]]+Append1[[#This Row],[DAY_LTC]] -> 33228 | AT2: 9776 | AU2: 3643 | AV2: 1306 | AW2: 11632 | AX2: 0 | AY2: 0 | AZ2: 2246 | BA2: 17962 | BB2: 0 | BC2: 2158 | BD2: 48723 | BE2: 71363118 | BF2: 60854375 | BG2: 14411053 | BH2: 57375871 | BI2: 0 | BJ2: 0 | BK2: 13990742 | BL2: 71149390 | BM2: 0 | BN2: 3307155 | BO2: 292451704 | BP2: 35210808 | BQ2: 28891174 | BR2: 5871109 | BS2: 39946555 | BT2: 0 | BU2: 0 | BV2: 13119193 | BW2: 58922262 | BX2: 0 | BY2: 4197975 | BZ2: 186159076 | CA2: 2272704 | CB2: 88051161 | CC2: 73421577 | CD2: 17883664 | CE2: 52659594 | CF2: 0 | CG2: 0 | CH2: 0 | CI2: 22267567 | CJ2: 93439065 | CK2: 0 | CL2: 3375466 | CM2: 0 | CN2: 0 | CO2: 0 | CP2: 6413785 | CQ2: 359784583 | CR2: 0 | CS2: 0 | CT2: 0 | CU2: 0 | CV2: 0 | CW2: 18033505 | CX2: 15996768 | CY2: 2236458 | CZ2: 44373536 | DA2: 0 | DB2: 0 | DC2: 4535581 | DD2: 32971878 | DE2: 0 | DF2: 678471 | DG2: 118826197 | DH2: 1181367 | DI2: 101757921 | DJ2: 0 | DK2: 837982 | DL2: 0 | DM2: 0 | DN2: 0 | DO2: 0 | DP2: 1494309 | DQ2: 137223161 | DR2: 0 | DS2: 0 | DT2: 0 | DU2: 0 | DV2: 0 | DW2: 0 | DX2: 0 | DY2: 0 | DZ2: 0 | EA2: 0 | EB2: 0 | EC2: 0 | ED2: 0
A3: 106171049 | B3: ADVENTIST HEALTH CLEARLAKE | C3: 20174 | D3: 43009 | E3: 43100 | F3: Open | G3: Lake | H3: 1 | I3: 115 | J3: Non Profit Corp. | K3: Comparable | L3: Rural | M3: 707-995-5820 | N3: 15630 18TH AVENUE | O3: CLEARLAKE | P3: 95422 | Q3: DAVID SANTOS | R3: 25 | S3: 25 | T3: 20 | U3: 195 | V3: 4 | W3: 17 | X3: 112 | Y3: 0 | Z3: 0 | AA3: 15 | AB3: 20 | AC3: 0 | AD3: 5 | AE3: 368 | AF3: 0 | AG3: 868 | AH3: 11 | AI3: 38 | AJ3: 447 | AK3: 0 | AL3: 0 | AM3: 63 | AN3: 62 | AO3: 0 | AP3: 8 | AQ3: 1497 | AR3: 0 | AS3: =Append1[[#This Row],[DAY_MCAR]]+Append1[[#This Row],[DAY_MCAR_MC]]+Append1[[#This Row],[DAY_MCAL]]+Append1[[#This Row],[DAY_MCAL_MC]]+Append1[[#This Row],[DAY_CNTY]]+Append1[[#This Row],[DAY_CNTY_MC]]+Append1[[#This Row],[DAY_THRD]]+Append1[[#This Row],[DAY_THRD_MC]]+Append1[[#This Row],[DAY_INDGNT]]+Append1[[#This Row],[DAY_OTH]]+Append1[[#This Row],[DAY_TOT]]+Append1[[#This Row],[DAY_LTC]] -> 2994 | AT3: 18850 | AU3: 236 | AV3: 6102 | AW3: 20417 | AX3: 0 | AY3: 0 | AZ3: 5841 | BA3: 2733 | BB3: 0 | BC3: 924 | BD3: 55103 | BE3: 9108603 | BF3: 401527 | BG3: 458182 | BH3: 5172868 | BI3: 0 | BJ3: 0 | BK3: 745016 | BL3: 835281 | BM3: 0 | BN3: 154674 | BO3: 16876151 | BP3: 16993939 | BQ3: 337344 | BR3: 3388635 | BS3: 15461946 | BT3: 0 | BU3: 0 | BV3: 1377158 | BW3: 5539582 | BX3: 0 | BY3: 1014594 | BZ3: 44113198 | CA3: 837648 | CB3: 14636391 | CC3: 579208 | CD3: 2402057 | CE3: 14238831 | CF3: 446943 | CG3: 0 | CH3: 0 | CI3: 343536 | CJ3: 4205989 | CK3: 0 | CL3: 2126830 | CM3: 0 | CN3: 0 | CO3: 0 | CP3: 1187033 | CQ3: 41004466 | CR3: 0 | CS3: 3354996 | CT3: 0 | CU3: 0 | CV3: 3354996 | CW3: 9842914 | CX3: 145722 | CY3: 1400652 | CZ3: 8890055 | DA3: 0 | DB3: 0 | DC3: 78938 | DD3: 3870071 | DE3: 0 | DF3: -888473 | DG3: 23339879 | DH3: 1269975 | DI3: 21613570 | DJ3: 0 | DK3: 21280 | DL3: 0 | DM3: 0 | DN3: 0 | DO3: 0 | DP3: 1224819 | DQ3: 31842591 | DR3: 0 | DS3: 0 | DT3: 0 | DU3: 0 | DV3: 0 | DW3: 0 | DX3: 0 | DY3: 0 | DZ3: 0 | EA3: 0 | EB3: 0 | EC3: 0 | ED3: 0
A4: 106040875 | B4: ADVENTIST HEALTH FEATHER RIVER | C4: 20174 | D4: 43009 | E4: 43100 | F4: Open | G4: Butte | H4: 1 | I4: 220 | J4: Church | K4: Comparable | M4: 530-877-9361 | N4: 5974 PENTZ ROAD | O4: PARADISE | P4: 95969 | Q4: MONTY KNITTEL | R4: 100 | S4: 100 | T4: 51 | U4: 617 | V4: 28 | W4: 47 | X4: 288 | Y4: 0 | Z4: 0 | AA4: 12 | AB4: 160 | AC4: 0 | AD4: 25 | AE4: 1177 | AF4: 0 | AG4: 2588 | AH4: 112 | AI4: 178 | AJ4: 880 | AK4: 0 | AL4: 0 | AM4: 27 | AN4: 455 | AO4: 0 | AP4: 61 | AQ4: 4301 | AR4: 0 | AS4: =Append1[[#This Row],[DAY_MCAR]]+Append1[[#This Row],[DAY_MCAR_MC]]+Append1[[#This Row],[DAY_MCAL]]+Append1[[#This Row],[DAY_MCAL_MC]]+Append1[[#This Row],[DAY_CNTY]]+Append1[[#This Row],[DAY_CNTY_MC]]+Append1[[#This Row],[DAY_THRD]]+Append1[[#This Row],[DAY_THRD_MC]]+Append1[[#This Row],[DAY_INDGNT]]+Append1[[#This Row],[DAY_OTH]]+Append1[[#This Row],[DAY_TOT]]+Append1[[#This Row],[DAY_LTC]] -> 8602 | AT4: 43568 | AU4: 1420 | AV4: 8061 | AW4: 27051 | AX4: 0 | AY4: 0 | AZ4: 1536 | BA4: 15412 | BB4: 0 | BC4: 1333 | BD4: 98381 | BE4: 67622023 | BF4: 2819880 | BG4: 4441575 | BH4: 20572218 | BI4: 0 | BJ4: 0 | BK4: 243598 | BL4: 14158556 | BM4: 0 | BN4: 1205706 | BO4: 111063556 | BP4: 93661341 | BQ4: 4226744 | BR4: 6930263 | BS4: 48359752 | BT4: 0 | BU4: 0 | BV4: 1337201 | BW4: 41649982 | BX4: 0 | BY4: 3131743 | BZ4: 199297026 | CA4: 1671586 | CB4: 140043971 | CC4: 6453618 | CD4: 9839806 | CE4: 47831823 | CF4: -55561 | CG4: 0 | CH4: 0 | CI4: 985992 | CJ4: 40331353 | CK4: 0 | CL4: 3665330 | CM4: 0 | CN4: 0 | CO4: 0 | CP4: 5969731 | CQ4: 256737649 | CR4: 0 | CS4: 0 | CT4: 0 | CU4: 0 | CV4: 0 | CW4: 19281147 | CX4: 484383 | CY4: 1321065 | CZ4: 20548740 | DA4: 0 | DB4: 0 | DC4: 43201 | DD4: 12695126 | DE4: 0 | DF4: -750729 | DG4: 53622933 | DH4: 4999673 | DI4: 52516178 | DJ4: 0 | DK4: 75243 | DL4: 0 | DM4: 0 | DN4: 0 | DO4: 0 | DP4: 600686 | DQ4: 55496213 | DR4: 0 | DS4: 0 | DT4: 0 | DU4: 0 | DV4: 0 | DW4: 0 | DX4: 0 | DY4: 0 | DZ4: 0 | EA4: 0 | EB4: 0 | EC4: 0 | ED4: 0
A5: 106190323 | B5: ADVENTIST HEALTH GLENDALE | C5: 20174 | D5: 43009 | E5: 43100 | F5: Open | G5: Los Angeles | H5: 11 | I5: 909 | J5: Church | K5: Comparable | M5: 818-409-8000 | N5: 1509 WILSON TERRACE | O5: GLENDALE | P5: 91206 | Q5: KEVIN ROBERTS | R5: 515 | S5: 462 | T5: 258 | U5: 2087 | V5: 416 | W5: 351 | X5: 857 | Y5: 0 | Z5: 0 | AA5: 72 | AB5: 1063 | AC5: 0 | AD5: 143 | AE5: 4989 | AF5: 0 | AG5: 11732 | AH5: 1666 | AI5: 2161 | AJ5: 3075 | AK5: 0 | AL5: 0 | AM5: 302 | AN5: 3898 | AO5: 0 | AP5: 513 | AQ5: 23347 | AR5: 0 | AS5: =Append1[[#This Row],[DAY_MCAR]]+Append1[[#This Row],[DAY_MCAR_MC]]+Append1[[#This Row],[DAY_MCAL]]+Append1[[#This Row],[DAY_MCAL_MC]]+Append1[[#This Row],[DAY_CNTY]]+Append1[[#This Row],[DAY_CNTY_MC]]+Append1[[#This Row],[DAY_THRD]]+Append1[[#This Row],[DAY_THRD_MC]]+Append1[[#This Row],[DAY_INDGNT]]+Append1[[#This Row],[DAY_OTH]]+Append1[[#This Row],[DAY_TOT]]+Append1[[#This Row],[DAY_LTC]] -> 46694 | AT5: 15308 | AU5: 1797 | AV5: 1257 | AW5: 9199 | AX5: 0 | AY5: 0 | AZ5: 3091 | BA5: 18033 | BB5: 0 | BC5: 1539 | BD5: 50224 | BE5: 192501958 | BF5: 37131928 | BG5: 31621277 | BH5: 71349447 | BI5: 0 | BJ5: 0 | BK5: 2188511 | BL5: 63651555 | BM5: 0 | BN5: 1816942 | BO5: 400261618 | BP5: 47868105 | BQ5: 12741879 | BR5: 6064401 | BS5: 45766658 | BT5: 0 | BU5: 0 | BV5: 2034365 | BW5: 50828732 | BX5: 0 | BY5: 13439358 | BZ5: 178743498 | CA5: 1353024 | CB5: 195736244 | CC5: 39647374 | CD5: 33934687 | CE5: 82184741 | CF5: 0 | CG5: 0 | CH5: 0 | CI5: 2138526 | CJ5: 52646291 | CK5: 0 | CL5: 2960341 | CM5: 0 | CN5: 0 | CO5: 0 | CP5: 13115679 | CQ5: 423716907 | CR5: 0 | CS5: 0 | CT5: 0 | CU5: 0 | CV5: 0 | CW5: 38804853 | CX5: 9013132 | CY5: 3705832 | CZ5: 34369691 | DA5: 0 | DB5: 0 | DC5: 1504194 | DD5: 59114403 | DE5: 0 | DF5: 8776104 | DG5: 155288209 | DH5: 2935654 | DI5: 112145651 | DJ5: 0 | DK5: 177146 | DL5: 0 | DM5: 0 | DN5: 0 | DO5: 0 | DP5: 2313385 | DQ5: 205118797 | DR5: 0 | DS5: 0 | DT5: 0 | DU5: 0 | DV5: 0 | DW5: 0 | DX5: 0 | DY5: 0 | DZ5: 0 | EA5: 0 | EB5: 0 | EC5: 0 | ED5: 0
A6: 106164029 | B6: ADVENTIST HEALTH HANFORD | C6: 20174 | D6: 43009 | E6: 43100 | F6: Open | G6: Kings | H6: 9 | I6: 615 | J6: Church | K6: Comparable | L6: Rural | M6: 559-582-9000 | N6: 115 MALL DRIVE | O6: HANFORD | P6: 93230 | Q6: WAYNE FERCH | R6: 230 | S6: 230 | T6: 122 | U6: 904 | V6: 153 | W6: 203 | X6: 882 | Y6: 0 | Z6: 0 | AA6: 151 | AB6: 377 | AC6: 2 | AD6: 85 | AE6: 2757 | AF6: 0 | AG6: 4584 | AH6: 678 | AI6: 780 | AJ6: 2940 | AK6: 0 | AL6: 0 | AM6: 447 | AN6: 1153 | AO6: 2 | AP6: 300 | AQ6: 10884 | AR6: 0 | AS6: =Append1[[#This Row],[DAY_MCAR]]+Append1[[#This Row],[DAY_MCAR_MC]]+Append1[[#This Row],[DAY_MCAL]]+Append1[[#This Row],[DAY_MCAL_MC]]+Append1[[#This Row],[DAY_CNTY]]+Append1[[#This Row],[DAY_CNTY_MC]]+Append1[[#This Row],[DAY_THRD]]+Append1[[#This Row],[DAY_THRD_MC]]+Append1[[#This Row],[DAY_INDGNT]]+Append1[[#This Row],[DAY_OTH]]+Append1[[#This Row],[DAY_TOT]]+Append1[[#This Row],[DAY_LTC]] -> 21768 | AT6: 13805 | AU6: 2032 | AV6: 3511 | AW6: 28941 | AX6: 0 | AY6: 0 | AZ6: 4537 | BA6: 15450 | BB6: 16 | BC6: 2842 | BD6: 71134 | BE6: 39810356 | BF6: 6458934 | BG6: 6161904 | BH6: 29503443 | BI6: 0 | BJ6: 0 | BK6: 4068300 | BL6: 11571065 | BM6: 25619 | BN6: 2453459 | BO6: 100053080 | BP6: 30739682 | BQ6: 6417684 | BR6: 8076606 | BS6: 68114587 | BT6: 0 | BU6: 0 | BV6: 10142611 | BW6: 33777390 | BX6: 49311 | BY6: 8213491 | BZ6: 165531362 | CA6: 7438010 | CB6: 64011090 | CC6: 10934754 | CD6: 13422518 | CE6: 55841578 | CF6: -500703 | CG6: 0 | CH6: 0 | CI6: 8436734 | CJ6: 20856183 | CK6: 0 | CL6: 2601162 | CM6: 0 | CN6: 0 | CO6: 0 | CP6: 10840275 | CQ6: 193881601 | CR6: 0 | CS6: 4002842 | CT6: 0 | CU6: 0 | CV6: 4002842 | CW6: 13973438 | CX6: 2152418 | CY6: 13576339 | CZ6: 19188628 | DA6: 0 | DB6: 0 | DC6: 2811770 | DD6: 23031345 | DE6: 3582 | DF6: 968163 | DG6: 75705683 | DH6: 659085 | DI6: 73036977 | DJ6: 0 | DK6: -2762995 | DL6: 0 | DM6: 0 | DN6: 0 | DO6: 0 | DP6: 2921916 | DQ6: 192203815 | DR6: 0 | DS6: 0 | DT6: 0 | DU6: 0 | DV6: 0 | DW6: 0 | DX6: 0 | DY6: 0 | DZ6: 0 | EA6: 0 | EB6: 0 | EC6: 0 | ED6: 0
A7: 106234038 | B7: ADVENTIST HEALTH HOWARD MEMORIAL | C7: 20174 | D7: 43009 | E7: 43100 | F7: Open | G7: Mendocino | H7: 1 | I7: 112 | J7: Non Profit Corp. | K7: Comparable | M7: 707-459-6801 | N7: 1 MARCELA DRIVE | O7: WILLITS | P7: 95490 | Q7: JASON WELLS | R7: 25 | S7: 25 | T7: 23 | U7: 248 | V7: 28 | W7: 16 | X7: 67 | Y7: 0 | Z7: 0 | AA7: 14 | AB7: 62 | AC7: 0 | AD7: 13 | AE7: 448 | AF7: 0 | AG7: 987 | AH7: 95 | AI7: 71 | AJ7: 259 | AK7: 0 | AL7: 0 | AM7: 63 | AN7: 197 | AO7: 0 | AP7: 38 | AQ7: 1710 | AR7: 0 | AS7: =Append1[[#This Row],[DAY_MCAR]]+Append1[[#This Row],[DAY_MCAR_MC]]+Append1[[#This Row],[DAY_MCAL]]+Append1[[#This Row],[DAY_MCAL_MC]]+Append1[[#This Row],[DAY_CNTY]]+Append1[[#This Row],[DAY_CNTY_MC]]+Append1[[#This Row],[DAY_THRD]]+Append1[[#This Row],[DAY_THRD_MC]]+Append1[[#This Row],[DAY_INDGNT]]+Append1[[#This Row],[DAY_OTH]]+Append1[[#This Row],[DAY_TOT]]+Append1[[#This Row],[DAY_LTC]] -> 3420 | AT7: 4770 | AU7: 429 | AV7: 178 | AW7: 3566 | AX7: 0 | AY7: 0 | AZ7: 310 | BA7: 3417 | BB7: 0 | BC7: 497 | BD7: 13167 | BE7: 13624482 | BF7: 1262162 | BG7: 883113 | BH7: 3944627 | BI7: 0 | BJ7: 0 | BK7: 225401 | BL7: 3873953 | BM7: 0 | BN7: 590569 | BO7: 24404307 | BP7: 6150104 | BQ7: 492621 | BR7: 549796 | BS7: 5486013 | BT7: 0 | BU7: 0 | BV7: 259371 | BW7: 4909870 | BX7: 0 | BY7: 817414 | BZ7: 18665189 | CA7: 909831 | CB7: 12424484 | CC7: 1220226 | CD7: 866212 | CE7: 9726042 | CF7: 0 | CG7: 0 | CH7: 0 | CI7: 297779 | CJ7: 3566538 | CK7: 0 | CL7: 934900 | CM7: 0 | CN7: 0 | CO7: 0 | CP7: 1065567 | CQ7: 31011579 | CR7: 0 | CS7: 1447009 | CT7: 0 | CU7: 0 | CV7: 1447009 | CW7: 7086385 | CX7: 477180 | CY7: 550284 | CZ7: 807498 | DA7: 0 | DB7: 0 | DC7: 71026 | DD7: 4517287 | DE7: 0 | DF7: -4734 | DG7: 13504926 | DH7: 568803 | DI7: 12823221 | DJ7: 0 | DK7: 415970 | DL7: 0 | DM7: 0 | DN7: 0 | DO7: 0 | DP7: 0 | DQ7: 61136675 | DR7: 0 | DS7: 0 | DT7: 0 | DU7: 0 | DV7: 0 | DW7: 0 | DX7: 0 | DY7: 0 | DZ7: 0 | EA7: 0 | EB7: 0 | EC7: 0 | ED7: 0
A8: 106390923 | B8: ADVENTIST HEALTH LODI MEMORIAL | C8: 20174 | D8: 43009 | E8: 43100 | F8: Open | G8: San Joaquin | H8: 6 | I8: 505 | J8: Non Profit Corp. | K8: Comparable | M8: 209-334-3411 | N8: 975 SOUTH FAIRMONT AVENUE | O8: LODI | P8: 95240 | Q8: DANIEL WOLCOTT | R8: 190 | S8: 190 | T8: 101 | U8: 1037 | V8: 206 | W8: 171 | X8: 539 | Y8: 0 | Z8: 0 | AA8: 42 | AB8: 353 | AC8: 3 | AD8: 38 | AE8: 2389 | AF8: 0 | AG8: 4146 | AH8: 896 | AI8: 603 | AJ8: 1933 | AK8: 0 | AL8: 0 | AM8: 161 | AN8: 1075 | AO8: 6 | AP8: 122 | AQ8: 8942 | AR8: 0 | AS8: =Append1[[#This Row],[DAY_MCAR]]+Append1[[#This Row],[DAY_MCAR_MC]]+Append1[[#This Row],[DAY_MCAL]]+Append1[[#This Row],[DAY_MCAL_MC]]+Append1[[#This Row],[DAY_CNTY]]+Append1[[#This Row],[DAY_CNTY_MC]]+Append1[[#This Row],[DAY_THRD]]+Append1[[#This Row],[DAY_THRD_MC]]+Append1[[#This Row],[DAY_INDGNT]]+Append1[[#This Row],[DAY_OTH]]+Append1[[#This Row],[DAY_TOT]]+Append1[[#This Row],[DAY_LTC]] -> 17884 | AT8: 20774 | AU8: 3361 | AV8: 3752 | AW8: 25150 | AX8: 0 | AY8: 0 | AZ8: 4710 | BA8: 14130 | BB8: 114 | BC8: 1374 | BD8: 73365 | BE8: 102878214 | BF8: 20949872 | BG8: 13411150 | BH8: 44450964 | BI8: 0 | BJ8: 0 | BK8: 5203980 | BL8: 30185051 | BM8: 231866 | BN8: 3019848 | BO8: 220330945 | BP8: 41343700 | BQ8: 8584396 | BR8: 7694154 | BS8: 46918591 | BT8: 0 | BU8: 0 | BV8: 6233552 | BW8: 33847035 | BX8: 153087 | BY8: 5039825 | BZ8: 149814340 | CA8: 5481324 | CB8: 146434384 | CC8: 25317532 | CD8: 15320317 | CE8: 57841858 | CF8: 0 | CG8: 0 | CH8: 0 | CI8: 7503312 | CJ8: 43101325 | CK8: 0 | CL8: 1984076 | CM8: 0 | CN8: 0 | CO8: 0 | CP8: 8775595 | CQ8: 311759723 | CR8: 0 | CS8: 518139 | CT8: 0 | CU8: 0 | CV8: 518139 | CW8: 13893937 | CX8: 2981248 | CY8: 10311096 | CZ8: 13034169 | DA8: 0 | DB8: 0 | DC8: 1703911 | DD8: 16794834 | DE8: 1051 | DF8: 183455 | DG8: 58903701 | DH8: 424765 | DI8: 54739688 | DJ8: 0 | DK8: -2987392 | DL8: 0 | DM8: 0 | DN8: 0 | DO8: 0 | DP8: 397676 | DQ8: 135770978 | DR8: 0 | DS8: 0 | DT8: 0 | DU8: 0 | DV8: 0 | DW8: 0 | DX8: 0 | DY8: 0 | DZ8: 0 | EA8: 0 | EB8: 0 | EC8: 0 | ED8: 0
A9: 106100797 | B9: ADVENTIST HEALTH REEDLEY | C9: 20174 | D9: 43009 | E9: 43100 | F9: Open | G9: Fresno | H9: 9 | I9: 607 | J9: District | K9: Comparable | L9: Rural | M9: 559-582-9000 | N9: 372 WEST CYPRESS AVENUE | O9: REEDLEY | P9: 93654 | Q9: WAYNE FERCH | R9: 49 | S9: 49 | T9: 15 | U9: 46 | V9: 7 | W9: 63 | X9: 260 | Y9: 0 | Z9: 0 | AA9: 1 | AB9: 62 | AC9: 0 | AD9: 8 | AE9: 447 | AF9: 0 | AG9: 204 | AH9: 23 | AI9: 142 | AJ9: 506 | AK9: 0 | AL9: 0 | AM9: 1 | AN9: 142 | AO9: 0 | AP9: 16 | AQ9: 1034 | AR9: 0 | AS9: =Append1[[#This Row],[DAY_MCAR]]+Append1[[#This Row],[DAY_MCAR_MC]]+Append1[[#This Row],[DAY_MCAL]]+Append1[[#This Row],[DAY_MCAL_MC]]+Append1[[#This Row],[DAY_CNTY]]+Append1[[#This Row],[DAY_CNTY_MC]]+Append1[[#This Row],[DAY_THRD]]+Append1[[#This Row],[DAY_THRD_MC]]+Append1[[#This Row],[DAY_INDGNT]]+Append1[[#This Row],[DAY_OTH]]+Append1[[#This Row],[DAY_TOT]]+Append1[[#This Row],[DAY_LTC]] -> 2068 | AT9: 19868 | AU9: 4040 | AV9: 14006 | AW9: 91659 | AX9: 0 | AY9: 0 | AZ9: 1400 | BA9: 19247 | BB9: 3539 | BC9: 2894 | BD9: 156653 | BE9: 1534647 | BF9: 153064 | BG9: 1222415 | BH9: 4398407 | BI9: 0 | BJ9: 0 | BK9: 8657 | BL9: 1167613 | BM9: 0 | BN9: 153470 | BO9: 8638273 | BP9: 8462781 | BQ9: 1546207 | BR9: 6062832 | BS9: 34988813 | BT9: 0 | BU9: 0 | BV9: 1106906 | BW9: 7743132 | BX9: 601050 | BY9: 2291282 | BZ9: 62803003 | CA9: 921316 | CB9: 4920055 | CC9: 1004291 | CD9: 11817451 | CE9: 4016484 | CF9: -2355983 | CG9: 0 | CH9: 0 | CI9: -5629 | CJ9: 3433285 | CK9: 0 | CL9: 1388496 | CM9: 0 | CN9: 0 | CO9: 0 | CP9: 2688990 | CQ9: 27828756 | CR9: 0 | CS9: 0 | CT9: 0 | CU9: 155462 | CV9: 155462 | CW9: 4067413 | CX9: 392927 | CY9: 1996570 | CZ9: 32852847 | DA9: 0 | DB9: 0 | DC9: 280959 | DD9: 3743004 | DE9: 101784 | DF9: 332478 | DG9: 43767982 | DH9: 986527 | DI9: 36432935 | DJ9: 0 | DK9: 314387 | DL9: 0 | DM9: 0 | DN9: 0 | DO9: 0 | DP9: 359595 | DQ9: 21735162 | DR9: 0 | DS9: 0 | DT9: 0 | DU9: 0 | DV9: 0 | DW9: 0 | DX9: 0 | DY9: 0 | DZ9: 0 | EA9: 0 | EB9: 0 | EC9: 0 | ED9: 0
A10: 106560525 | B10: ADVENTIST HEALTH SIMI VALLEY | C10: 20174 | D10: 43009 | E10: 43100 | F10: Open | G10: Ventura | H10: 10 | I10: 813 | J10: Church | K10: Comparable | M10: 805-955-6000 | N10: 2975 SYCAMORE DRIVE | O10: SIMI VALLEY | P10: 93065 | Q10: JENNIFER SWENSON | R10: 144 | S10: 85 | T10: 74 | U10: 666 | V10: 176 | W10: 45 | X10: 244 | Y10: 0 | Z10: 0 | AA10: 31 | AB10: 520 | AC10: 0 | AD10: 42 | AE10: 1724 | AF10: 0 | AG10: 2845 | AH10: 674 | AI10: 152 | AJ10: 842 | AK10: 0 | AL10: 0 | AM10: 99 | AN10: 1734 | AO10: 0 | AP10: 124 | AQ10: 6470 | AR10: 0 | AS10: =Append1[[#This Row],[DAY_MCAR]]+Append1[[#This Row],[DAY_MCAR_MC]]+Append1[[#This Row],[DAY_MCAL]]+Append1[[#This Row],[DAY_MCAL_MC]]+Append1[[#This Row],[DAY_CNTY]]+Append1[[#This Row],[DAY_CNTY_MC]]+Append1[[#This Row],[DAY_THRD]]+Append1[[#This Row],[DAY_THRD_MC]]+Append1[[#This Row],[DAY_INDGNT]]+Append1[[#This Row],[DAY_OTH]]+Append1[[#This Row],[DAY_TOT]]+Append1[[#This Row],[DAY_LTC]] -> 12940 | AT10: 5838 | AU10: 760 | AV10: 427 | AW10: 3512 | AX10: 0 | AY10: 0 | AZ10: 2692 | BA10: 10032 | BB10: 0 | BC10: 749 | BD10: 24010 | BE10: 45164367 | BF10: 11654673 | BG10: 2967630 | BH10: 11686044 | BI10: 0 | BJ10: 0 | BK10: 1159441 | BL10: 26084904 | BM10: 0 | BN10: 334815 | BO10: 99051874 | BP10: 13924573 | BQ10: 5501097 | BR10: 2732854 | BS10: 13091342 | BT10: 0 | BU10: 0 | BV10: 993153 | BW10: 29694081 | BX10: 0 | BY10: 2452187 | BZ10: 68389287 | CA10: 1105470 | CB10: 46959193 | CC10: 11970047 | CD10: 4101945 | CE10: 24678197 | CF10: 0 | CG10: 0 | CH10: 0 | CI10: 883661 | CJ10: 35142772 | CK10: 0 | CL10: 1671997 | CM10: 0 | CN10: 0 | CO10: 0 | CP10: 5792787 | CQ10: 132306069 | CR10: 0 | CS10: 0 | CT10: 0 | CU10: 0 | CV10: 0 | CW10: 10097716 | CX10: 5107520 | CY10: 1587979 | CZ10: 144809 | DA10: 0 | DB10: 0 | DC10: 830838 | DD10: 19243516 | DE10: 0 | DF10: -1877286 | DG10: 35135092 | DH10: 804786 | DI10: 38280988 | DJ10: 0 | DK10: 154685 | DL10: 0 | DM10: 0 | DN10: 0 | DO10: 0 | DP10: 3107043 | DQ10: 132761888 | DR10: 0 | DS10: 0 | DT10: 0 | DU10: 0 | DV10: 0 | DW10: 0 | DX10: 0 | DY10: 0 | DZ10: 0 | EA10: 0 | EB10: 0 | EC10: 0 | ED10: 0
A11: 106554011 | B11: ADVENTIST HEALTH SONORA - GREENLEY | C11: 20174 | D11: 43009 | E11: 43100 | F11: Open | G11: Tuolumne | H11: 6 | I11: 513 | J11: Church | K11: Comparable | L11: Rural | M11: 209-536-5000 | N11: 1000 GREENLEY ROAD | O11: SONORA | P11: 95370 | Q11: MICHELLE FUENTES | R11: 152 | S11: 152 | T11: 117 | U11: 623 | V11: 29 | W11: 26 | X11: 185 | Y11: 0 | Z11: 0 | AA11: 40 | AB11: 194 | AC11: 1 | AD11: 18 | AE11: 1116 | AF11: 25 | AG11: 2616 | AH11: 127 | AI11: 5983 | AJ11: 699 | AK11: 0 | AL11: 0 | AM11: 261 | AN11: 696 | AO11: 1 | AP11: 20 | AQ11: 10403 | AR11: 6072 | AS11: =Append1[[#This Row],[DAY_MCAR]]+Append1[[#This Row],[DAY_MCAR_MC]]+Append1[[#This Row],[DAY_MCAL]]+Append1[[#This Row],[DAY_MCAL_MC]]+Append1[[#This Row],[DAY_CNTY]]+Append1[[#This Row],[DAY_CNTY_MC]]+Append1[[#This Row],[DAY_THRD]]+Append1[[#This Row],[DAY_THRD_MC]]+Append1[[#This Row],[DAY_INDGNT]]+Append1[[#This Row],[DAY_OTH]]+Append1[[#This Row],[DAY_TOT]]+Append1[[#This Row],[DAY_LTC]] -> 26878 | AT11: 49228 | AU11: 2050 | AV11: 4302 | AW11: 16992 | AX11: 0 | AY11: 0 | AZ11: 6985 | BA11: 26407 | BB11: 23 | BC11: 2145 | BD11: 108132 | BE11: 46072278 | BF11: 2231309 | BG11: 4112991 | BH11: 12297683 | BI11: 0 | BJ11: 0 | BK11: 3986169 | BL11: 14788267 | BM11: 121652 | BN11: 251794 | BO11: 83862143 | BP11: 79005882 | BQ11: 3821085 | BR11: 4203507 | BS11: 22905408 | BT11: 0 | BU11: 0 | BV11: 8098811 | BW11: 36762240 | BX11: 69341 | BY11: 2046027 | BZ11: 156912301 | CA11: 1945017 | CB11: 104128444 | CC11: 4368103 | CD11: 1339449 | CE11: 29517278 | CF11: 0 | CG11: 0 | CH11: 0 | CI11: 6005578 | CJ11: 26144096 | CK11: 0 | CL11: 2029165 | CM11: 0 | CN11: 0 | CO11: 0 | CP11: 4478410 | CQ11: 179955540 | CR11: 0 | CS11: 0 | CT11: 0 | CU11: 0 | CV11: 0 | CW11: 23231828 | CX11: 1265696 | CY11: 7949997 | CZ11: 3577857 | DA11: 0 | DB11: 0 | DC11: 3407562 | DD11: 20970954 | DE11: 2930 | DF11: 412080 | DG11: 60818904 | DH11: 2051373 | DI11: 54717601 | DJ11: 0 | DK11: 215023 | DL11: 0 | DM11: 0 | DN11: 0 | DO11: 0 | DP11: 10085538 | DQ11: 84544054 | DR11: 0 | DS11: 0 | DT11: 0 | DU11: 0 | DV11: 0 | DW11: 0 | DX11: 0 | DY11: 0 | DZ11: 0 | EA11: 0 | EB11: 0 | EC11: 0 | ED11: 0
A12: 106281078 | B12: ADVENTIST HEALTH ST. HELENA | C12: 20174 | D12: 43009 | E12: 43100 | F12: Open | G12: Napa | H12: 3 | I12: 407 | J12: Non Profit Corp. | K12: Comparable | M12: 707-963-3611 | N12: 10 WOODLAND ROAD | O12: ST. HELENA | P12: 94574 | Q12: STEVEN HERBER | R12: 151 | S12: 151 | T12: 71 | U12: 616 | V12: 50 | W12: 154 | X12: 140 | Y12: 0 | Z12: 0 | AA12: 28 | AB12: 209 | AC12: 0 | AD12: 1 | AE12: 1198 | AF12: 0 | AG12: 3048 | AH12: 286 | AI12: 1230 | AJ12: 585 | AK12: 0 | AL12: 0 | AM12: 254 | AN12: 754 | AO12: 0 | AP12: 2 | AQ12: 6159 | AR12: 0 | AS12: =Append1[[#This Row],[DAY_MCAR]]+Append1[[#This Row],[DAY_MCAR_MC]]+Append1[[#This Row],[DAY_MCAL]]+Append1[[#This Row],[DAY_MCAL_MC]]+Append1[[#This Row],[DAY_CNTY]]+Append1[[#This Row],[DAY_CNTY_MC]]+Append1[[#This Row],[DAY_THRD]]+Append1[[#This Row],[DAY_THRD_MC]]+Append1[[#This Row],[DAY_INDGNT]]+Append1[[#This Row],[DAY_OTH]]+Append1[[#This Row],[DAY_TOT]]+Append1[[#This Row],[DAY_LTC]] -> 12318 | AT12: 7053 | AU12: 144 | AV12: 164 | AW12: 1424 | AX12: 0 | AY12: 0 | AZ12: 1172 | BA12: 3884 | BB12: 0 | BC12: 184 | BD12: 14025 | BE12: 89882183 | BF12: 11649080 | BG12: 11066552 | BH12: 8790749 | BI12: 0 | BJ12: 0 | BK12: 2258544 | BL12: 27807792 | BM12: 0 | BN12: 701441 | BO12: 152156341 | BP12: 40500514 | BQ12: 806876 | BR12: 2246735 | BS12: 10626816 | BT12: 0 | BU12: 0 | BV12: 2579497 | BW12: 21449495 | BX12: 0 | BY12: 1444802 | BZ12: 79654735 | CA12: 457013 | CB12: 107395777 | CC12: 6341487 | CD12: 11842404 | CE12: 10222215 | CF12: -1401796 | CG12: 0 | CH12: 0 | CI12: 2531638 | CJ12: 29385050 | CK12: 0 | CL12: 3485791 | CM12: 0 | CN12: 0 | CO12: 0 | CP12: 3190774 | CQ12: 173450353 | CR12: 0 | CS12: 6371417 | CT12: 0 | CU12: 0 | CV12: 6371417 | CW12: 22004887 | CX12: 6021987 | CY12: 2019820 | CZ12: 16764255 | DA12: 0 | DB12: 0 | DC12: 1974095 | DD12: 18097014 | DE12: 0 | DF12: -2149918 | DG12: 64732140 | DH12: 1680512 | DI12: 58996235 | DJ12: 0 | DK12: 26582 | DL12: 0 | DM12: 0 | DN12: 0 | DO12: 0 | DP12: 1005365 | DQ12: 87857460 | DR12: 0 | DS12: 0 | DT12: 0 | DU12: 0 | DV12: 0 | DW12: 0 | DX12: 0 | DY12: 0 | DZ12: 0 | EA12: 0 | EB12: 0 | EC12: 0 | ED12: 0
A13: 106150808 | B13: ADVENTIST HEALTH TEHACHAPI VALLEY | C13: 20174 | D13: 43009 | E13: 43100 | F13: Open | G13: Kern | H13: 9 | I13: 623 | J13: District | K13: Comparable | L13: Rural | M13: 661-823-3000 | N13: 115 WEST E STREET | O13: TEHACHAPI | P13: 93561 | Q13: DAVID EASTMAN | R13: 28 | S13: 24 | T13: 14 | U13: 8 | V13: 2 | W13: 0 | X13: 6 | Y13: 0 | Z13: 0 | AA13: 3 | AB13: 1 | AC13: 0 | AD13: 0 | AE13: 20 | AF13: 0 | AG13: 22 | AH13: 5 | AI13: 0 | AJ13: 12 | AK13: 0 | AL13: 0 | AM13: 4 | AN13: 3 | AO13: 0 | AP13: 0 | AQ13: 46 | AR13: 0 | AS13: =Append1[[#This Row],[DAY_MCAR]]+Append1[[#This Row],[DAY_MCAR_MC]]+Append1[[#This Row],[DAY_MCAL]]+Append1[[#This Row],[DAY_MCAL_MC]]+Append1[[#This Row],[DAY_CNTY]]+Append1[[#This Row],[DAY_CNTY_MC]]+Append1[[#This Row],[DAY_THRD]]+Append1[[#This Row],[DAY_THRD_MC]]+Append1[[#This Row],[DAY_INDGNT]]+Append1[[#This Row],[DAY_OTH]]+Append1[[#This Row],[DAY_TOT]]+Append1[[#This Row],[DAY_LTC]] -> 92 | AT13: 1335 | AU13: 345 | AV13: 744 | AW13: 5326 | AX13: 0 | AY13: 0 | AZ13: 315 | BA13: 1088 | BB13: 0 | BC13: 451 | BD13: 9604 | BE13: 55216 | BF13: 14370 | BG13: 0 | BH13: 44017 | BI13: 0 | BJ13: 0 | BK13: 34464 | BL13: 5998 | BM13: 0 | BN13: 0 | BO13: 154065 | BP13: 3106973 | BQ13: 1746755 | BR13: 1004832 | BS13: 6237997 | BT13: 0 | BU13: 0 | BV13: 332867 | BW13: 3941182 | BX13: 0 | BY13: 525815 | BZ13: 16896421 | CA13: 273100 | CB13: 2860557 | CC13: 1045127 | CD13: -1612495 | CE13: 2777723 | CF13: -34449 | CG13: 0 | CH13: 0 | CI13: 282618 | CJ13: 2517688 | CK13: 0 | CL13: 2072977 | CM13: 0 | CN13: 0 | CO13: 0 | CP13: 918204 | CQ13: 11101050 | CR13: 0 | CS13: 3150 | CT13: 0 | CU13: 0 | CV13: 3150 | CW13: 432655 | CX13: 715998 | CY13: 2617326 | CZ13: 3541890 | DA13: 0 | DB13: 0 | DC13: 678715 | DD13: 835490 | DE13: 0 | DF13: -2869488 | DG13: 5952586 | DH13: 11332 | DI13: 6521466 | DJ13: 0 | DK13: 15897 | DL13: 0 | DM13: 0 | DN13: 0 | DO13: 0 | DP13: 2135395 | DQ13: 30661791 | DR13: 0 | DS13: 0 | DT13: 0 | DU13: 0 | DV13: 0 | DW13: 0 | DX13: 0 | DY13: 0 | DZ13: 0 | EA13: 0 | EB13: 0 | EC13: 0 | ED13: 0
A14: 106231396 | B14: ADVENTIST HEALTH UKIAH VALLEY | C14: 20174 | D14: 43009 | E14: 43100 | F14: Open | G14: Mendocino | H14: 1 | I14: 113 | J14: Church | K14: Comparable | L14: Rural | M14: 707-462-3111 | N14: 275 HOSPITAL DRIVE | O14: UKIAH | P14: 95482 | Q14: GWEN MATTHEWS | R14: 67 | S14: 50 | T14: 35 | U14: 348 | V14: 37 | W14: 58 | X14: 304 | Y14: 0 | Z14: 0 | AA14: 19 | AB14: 129 | AC14: 0 | AD14: 16 | AE14: 911 | AF14: 0 | AG14: 1316 | AH14: 118 | AI14: 158 | AJ14: 829 | AK14: 0 | AL14: 0 | AM14: 56 | AN14: 353 | AO14: 0 | AP14: 68 | AQ14: 2898 | AR14: 0 | AS14: =Append1[[#This Row],[DAY_MCAR]]+Append1[[#This Row],[DAY_MCAR_MC]]+Append1[[#This Row],[DAY_MCAL]]+Append1[[#This Row],[DAY_MCAL_MC]]+Append1[[#This Row],[DAY_CNTY]]+Append1[[#This Row],[DAY_CNTY_MC]]+Append1[[#This Row],[DAY_THRD]]+Append1[[#This Row],[DAY_THRD_MC]]+Append1[[#This Row],[DAY_INDGNT]]+Append1[[#This Row],[DAY_OTH]]+Append1[[#This Row],[DAY_TOT]]+Append1[[#This Row],[DAY_LTC]] -> 5796 | AT14: 21711 | AU14: 1449 | AV14: 1049 | AW14: 17324 | AX14: 0 | AY14: 0 | AZ14: 2019 | BA14: 15719 | BB14: 0 | BC14: 1378 | BD14: 60649 | BE14: 15410138 | BF14: 1499435 | BG14: 2306900 | BH14: 10625189 | BI14: 0 | BJ14: 0 | BK14: 100781 | BL14: 6371852 | BM14: 0 | BN14: 736840 | BO14: 37051135 | BP14: 32970299 | BQ14: 2031697 | BR14: 1963927 | BS14: 22342177 | BT14: 0 | BU14: 0 | BV14: 660530 | BW14: 21087607 | BX14: 0 | BY14: 1915538 | BZ14: 82971775 | CA14: 188206 | CB14: 36415592 | CC14: 2838752 | CD14: 2864613 | CE14: 27272966 | CF14: 283801 | CG14: 0 | CH14: 0 | CI14: 750639 | CJ14: 13521334 | CK14: 0 | CL14: 1986874 | CM14: 0 | CN14: 0 | CO14: 0 | CP14: 3411326 | CQ14: 89534103 | CR14: 0 | CS14: 11097862 | CT14: 0 | CU14: 0 | CV14: 11097862 | CW14: 10903672 | CX14: 623279 | CY14: 1430645 | CZ14: 16300955 | DA14: 0 | DB14: 0 | DC14: -46157 | DD14: 12623436 | DE14: 0 | DF14: -249161 | DG14: 41586669 | DH14: 634904 | DI14: 34384258 | DJ14: 0 | DK14: 20659 | DL14: 0 | DM14: 0 | DN14: 0 | DO14: 0 | DP14: 8989499 | DQ14: 59408731 | DR14: 0 | DS14: 0 | DT14: 0 | DU14: 0 | DV14: 0 | DW14: 0 | DX14: 0 | DY14: 0 | DZ14: 0 | EA14: 0 | EB14: 0 | EC14: 0 | ED14: 0
A15: 106481015 | B15: ADVENTIST HEALTH VALLEJO | C15: 20174 | D15: 43009 | E15: 43100 | F15: Open | G15: Solano | H15: 3 | I15: 409 | J15: Non Profit Corp. | K15: Comparable | M15: 707-963-3611 | N15: 525 OREGON STREET | O15: VALLEJO | P15: 94590 | Q15: DR STEVE HERBER | R15: 61 | S15: 61 | T15: 60 | U15: 139 | V15: 33 | W15: 121 | X15: 0 | Y15: 0 | Z15: 0 | AA15: 35 | AB15: 288 | AC15: 0 | AD15: 0 | AE15: 616 | AF15: 0 | AG15: 1649 | AH15: 236 | AI15: 1083 | AJ15: 0 | AK15: 0 | AL15: 0 | AM15: 230 | AN15: 1911 | AO15: 0 | AP15: 0 | AQ15: 5109 | AR15: 0 | AS15: =Append1[[#This Row],[DAY_MCAR]]+Append1[[#This Row],[DAY_MCAR_MC]]+Append1[[#This Row],[DAY_MCAL]]+Append1[[#This Row],[DAY_MCAL_MC]]+Append1[[#This Row],[DAY_CNTY]]+Append1[[#This Row],[DAY_CNTY_MC]]+Append1[[#This Row],[DAY_THRD]]+Append1[[#This Row],[DAY_THRD_MC]]+Append1[[#This Row],[DAY_INDGNT]]+Append1[[#This Row],[DAY_OTH]]+Append1[[#This Row],[DAY_TOT]]+Append1[[#This Row],[DAY_LTC]] -> 10218 | AT15: 623 | AU15: 0 | AV15: 0 | AW15: 0 | AX15: 0 | AY15: 0 | AZ15: 262 | BA15: 250 | BB15: 0 | BC15: 21 | BD15: 1156 | BE15: 6168864 | BF15: 810033 | BG15: 3940124 | BH15: 0 | BI15: 0 | BJ15: 0 | BK15: 1142163 | BL15: 7885259 | BM15: 0 | BN15: 0 | BO15: 19946443 | BP15: 1608737 | BQ15: 0 | BR15: 0 | BS15: 0 | BT15: 0 | BU15: 0 | BV15: 364980 | BW15: 753854 | BX15: 0 | BY15: 66647 | BZ15: 2794218 | CA15: 128776 | CB15: 8286635 | CC15: -435751 | CD15: 3680709 | CE15: 60282 | CF15: 0 | CG15: 0 | CH15: 0 | CI15: 414993 | CJ15: -164201 | CK15: 0 | CL15: 794142 | CM15: 0 | CN15: 0 | CO15: 0 | CP15: 273009 | CQ15: 13038594 | CR15: 0 | CS15: 0 | CT15: 0 | CU15: 0 | CV15: 0 | CW15: -739353 | CX15: 1206644 | CY15: -395823 | CZ15: -57926 | DA15: 0 | DB15: 0 | DC15: 1130076 | DD15: 8303649 | DE15: 0 | DF15: 254800 | DG15: 9702067 | DH15: 61263 | DI15: 7967569 | DJ15: 0 | DK15: 0 | DL15: 0 | DM15: 0 | DN15: 0 | DO15: 0 | DP15: 0 | DQ15: 0 | DR15: 0 | DS15: 0 | DT15: 0 | DU15: 0 | DV15: 0 | DW15: 0 | DX15: 0 | DY15: 0 | DZ15: 0 | EA15: 0 | EB15: 0 | EC15: 0 | ED15: 0
A16: 106190878 | B16: ADVENTIST HEALTH WHITE MEMORIAL | C16: 20174 | D16: 43009 | E16: 43100 | F16: Open | G16: Los Angeles | H16: 11 | I16: 925 | J16: Non Profit Corp. | K16: Comparable | L16: Teaching | M16: 323-268-5000 | N16: 1720 CESAR E. CHAVEZ AVENUE | O16: LOS ANGELES | P16: 90033 | Q16: JOHN RAFFOUL | R16: 353 | S16: 353 | T16: 236 | U16: 869 | V16: 592 | W16: 1126 | X16: 1566 | Y16: 0 | Z16: 0 | AA16: 44 | AB16: 667 | AC16: 0 | AD16: 107 | AE16: 4971 | AF16: 0 | AG16: 5023 | AH16: 2234 | AI16: 5386 | AJ16: 5794 | AK16: 0 | AL16: 0 | AM16: 223 | AN16: 2097 | AO16: 0 | AP16: 250 | AQ16: 21007 | AR16: 0 | AS16: =Append1[[#This Row],[DAY_MCAR]]+Append1[[#This Row],[DAY_MCAR_MC]]+Append1[[#This Row],[DAY_MCAL]]+Append1[[#This Row],[DAY_MCAL_MC]]+Append1[[#This Row],[DAY_CNTY]]+Append1[[#This Row],[DAY_CNTY_MC]]+Append1[[#This Row],[DAY_THRD]]+Append1[[#This Row],[DAY_THRD_MC]]+Append1[[#This Row],[DAY_INDGNT]]+Append1[[#This Row],[DAY_OTH]]+Append1[[#This Row],[DAY_TOT]]+Append1[[#This Row],[DAY_LTC]] -> 42014 | AT16: 7438 | AU16: 4328 | AV16: 4815 | AW16: 13112 | AX16: 0 | AY16: 0 | AZ16: 2053 | BA16: 7399 | BB16: 0 | BC16: 1864 | BD16: 41009 | BE16: 88121172 | BF16: 58435399 | BG16: 79955471 | BH16: 129948050 | BI16: 0 | BJ16: 0 | BK16: 1066617 | BL16: 36939547 | BM16: 0 | BN16: 3090726 | BO16: 397556982 | BP16: 24015834 | BQ16: 24935181 | BR16: 19094785 | BS16: 70043899 | BT16: 0 | BU16: 0 | BV16: 859141 | BW16: 28025221 | BX16: 0 | BY16: 4060707 | BZ16: 171034768 | CA16: -666694 | CB16: 84309825 | CC16: 69622282 | CD16: 79101294 | CE16: 116193469 | CF16: -4200677 | CG16: 0 | CH16: 0 | CI16: 5339405 | CJ16: 46543730 | CK16: 0 | CL16: 5564474 | CM16: 0 | CN16: 0 | CO16: 0 | CP16: 18845425 | CQ16: 420652533 | CR16: 50128 | CS16: 8638600 | CT16: 0 | CU16: 0 | CV16: 8688728 | CW16: 22076225 | CX16: 12917099 | CY16: 19522606 | CZ16: 97132405 | DA16: 0 | DB16: 0 | DC16: -3565764 | DD16: 10056348 | DE16: 0 | DF16: -1510974 | DG16: 156627945 | DH16: 6778659 | DI16: 104937463 | DJ16: 0 | DK16: 1786754 | DL16: 0 | DM16: 0 | DN16: 0 | DO16: 0 | DP16: 5116278 | DQ16: 158766508 | DR16: 0 | DS16: 0 | DT16: 0 | DU16: 0 | DV16: 0 | DW16: 0 | DX16: 0 | DY16: 0 | DZ16: 0 | EA16: 0 | EB16: 0 | EC16: 0 | ED16: 0
A17: 106301098 | B17: AHMC ANAHEIM REGIONAL MEDICAL CENTER | C17: 20174 | D17: 43009 | E17: 43100 | F17: Open | G17: Orange | H17: 13 | I17: 1012 | J17: Non Profit Other | K17: Comparable | M17: 714-999-5102 | N17: 1111 WEST LA PALMA AVENUE | O17: ANAHEIM | P17: 92801 | Q17: RICHARD CASTRO | R17: 223 | S17: 223 | T17: 223 | U17: 640 | V17: 446 | W17: 326 | X17: 795 | Y17: 0 | Z17: 0 | AA17: 20 | AB17: 366 | AC17: 0 | AD17: 67 | AE17: 2660 | AF17: 0 | AG17: 3123 | AH17: 2396 | AI17: 1473 | AJ17: 2975 | AK17: 0 | AL17: 0 | AM17: 148 | AN17: 925 | AO17: 0 | AP17: 174 | AQ17: 11214 | AR17: 0 | AS17: =Append1[[#This Row],[DAY_MCAR]]+Append1[[#This Row],[DAY_MCAR_MC]]+Append1[[#This Row],[DAY_MCAL]]+Append1[[#This Row],[DAY_MCAL_MC]]+Append1[[#This Row],[DAY_CNTY]]+Append1[[#This Row],[DAY_CNTY_MC]]+Append1[[#This Row],[DAY_THRD]]+Append1[[#This Row],[DAY_THRD_MC]]+Append1[[#This Row],[DAY_INDGNT]]+Append1[[#This Row],[DAY_OTH]]+Append1[[#This Row],[DAY_TOT]]+Append1[[#This Row],[DAY_LTC]] -> 22428 | AT17: 2139 | AU17: 1621 | AV17: 1820 | AW17: 5104 | AX17: 0 | AY17: 0 | AZ17: 428 | BA17: 2819 | BB17: 0 | BC17: 954 | BD17: 14885 | BE17: 59135165 | BF17: 49109383 | BG17: 21560270 | BH17: 58378353 | BI17: 0 | BJ17: 0 | BK17: 2564368 | BL17: 29332726 | BM17: 0 | BN17: 4009529 | BO17: 224089794 | BP17: 15836944 | BQ17: 23725753 | BR17: 7331467 | BS17: 31314960 | BT17: 0 | BU17: 0 | BV17: 2808802 | BW17: 21535734 | BX17: 0 | BY17: 2694065 | BZ17: 105247725 | CA17: 1816523 | CB17: 65267134 | CC17: 63124742 | CD17: 26159547 | CE17: 51231602 | CF17: -787500 | CG17: 0 | CH17: 0 | CI17: 4283934 | CJ17: 42137072 | CK17: 0 | CL17: 0 | CM17: 0 | CN17: 0 | CO17: 0 | CP17: 2080689 | CQ17: 255313743 | CR17: 0 | CS17: 0 | CT17: 0 | CU17: 0 | CV17: 0 | CW17: 9704975 | CX17: 9710394 | CY17: 3519690 | CZ17: 38461712 | DA17: 0 | DB17: 0 | DC17: 1089235 | DD17: 8731388 | DE17: 0 | DF17: 2806382 | DG17: 74023776 | DH17: 141495 | DI17: 51206733 | DJ17: 0 | DK17: 0 | DL17: 0 | DM17: 0 | DN17: 0 | DO17: 0 | DP17: 77388 | DQ17: 5762288 | DR17: 0 | DS17: 0 | DT17: 0 | DU17: 0 | DV17: 0 | DW17: 0 | DX17: 0 | DY17: 0 | DZ17: 0 | EA17: 0 | EB17: 0 | EC17: 0 | ED17: 0
A18: 106010735 | B18: ALAMEDA HOSPITAL | C18: 20174 | D18: 43009 | E18: 43100 | F18: Open | G18: Alameda | H18: 5 | I18: 417 | J18: Non Profit Corp. | K18: Comparable | M18: 510-437-4800 | N18: 2070 CLINTON AVENUE | O18: ALAMEDA | P18: 94501 | Q18: DELVECCHIO FINLEY | R18: 251 | S18: 217 | T18: 217 | U18: 326 | V18: 46 | W18: 55 | X18: 126 | Y18: 0 | Z18: 14 | AA18: 11 | AB18: 74 | AC18: 0 | AD18: 12 | AE18: 664 | AF18: 0 | AG18: 4571 | AH18: 407 | AI18: 11758 | AJ18: 941 | AK18: 0 | AL18: 54 | AM18: 36 | AN18: 984 | AO18: 0 | AP18: 226 | AQ18: 18977 | AR18: 0 | AS18: =Append1[[#This Row],[DAY_MCAR]]+Append1[[#This Row],[DAY_MCAR_MC]]+Append1[[#This Row],[DAY_MCAL]]+Append1[[#This Row],[DAY_MCAL_MC]]+Append1[[#This Row],[DAY_CNTY]]+Append1[[#This Row],[DAY_CNTY_MC]]+Append1[[#This Row],[DAY_THRD]]+Append1[[#This Row],[DAY_THRD_MC]]+Append1[[#This Row],[DAY_INDGNT]]+Append1[[#This Row],[DAY_OTH]]+Append1[[#This Row],[DAY_TOT]]+Append1[[#This Row],[DAY_LTC]] -> 37954 | AT18: 1954 | AU18: 285 | AV18: 213 | AW18: 1888 | AX18: 0 | AY18: 83 | AZ18: 338 | BA18: 1376 | BB18: 0 | BC18: 1493 | BD18: 7630 | BE18: 28843292 | BF18: 3165124 | BG18: 17792965 | BH18: 9924367 | BI18: 0 | BJ18: 1794348 | BK18: 542200 | BL18: 4352546 | BM18: 0 | BN18: 862512 | BO18: 67277354 | BP18: 11691106 | BQ18: 1873071 | BR18: 1252337 | BS18: 9712552 | BT18: 0 | BU18: 1182425 | BV18: 1080459 | BW18: 5931698 | BX18: 0 | BY18: 1587646 | BZ18: 34311294 | CA18: 1838844 | CB18: 33564138 | CC18: 4004000 | CD18: 16357960 | CE18: 16606086 | CF18: -632250 | CG18: 0 | CH18: 2976773 | CI18: 1357584 | CJ18: 7262406 | CK18: 0 | CL18: 488807 | CM18: 0 | CN18: 0 | CO18: 0 | CP18: 0 | CQ18: 83824348 | CR18: 0 | CS18: 0 | CT18: 415784 | CU18: 0 | CV18: 415784 | CW18: 6970260 | CX18: 1034195 | CY18: 3319592 | CZ18: 3030833 | DA18: 0 | DB18: 415784 | DC18: 265075 | DD18: 3021838 | DE18: 0 | DF18: 122507 | DG18: 18180084 | DH18: 384106 | DI18: 26859719 | DJ18: 0 | DK18: 1923909 | DL18: 0 | DM18: 0 | DN18: 0 | DO18: 0 | DP18: 0 | DQ18: 7328505 | DR18: 0 | DS18: 0 | DT18: 0 | DU18: 0 | DV18: 0 | DW18: 0 | DX18: 0 | DY18: 0 | DZ18: 0 | EA18: 0 | EB18: 0 | EC18: 0 | ED18: 0
A19: 106190017 | B19: ALHAMBRA HOSPITAL MEDICAL CENTER | C19: 20174 | D19: 43009 | E19: 43100 | F19: Open | G19: Los Angeles | H19: 11 | I19: 913 | J19: Investor - Ptnr. | K19: Comparable | M19: 626-570-1606 | N19: 100 SOUTH RAYMOND AVENUE | O19: ALHAMBRA | P19: 91801 | Q19: IRIS LAI | R19: 144 | S19: 144 | T19: 144 | U19: 414 | V19: 303 | W19: 36 | X19: 515 | Y19: 0 | Z19: 0 | AA19: 7 | AB19: 115 | AC19: 0 | AD19: 14 | AE19: 1404 | AF19: 4 | AG19: 2796 | AH19: 1296 | AI19: 633 | AJ19: 3471 | AK19: 0 | AL19: 0 | AM19: 19 | AN19: 463 | AO19: 0 | AP19: 62 | AQ19: 8740 | AR19: 2364 | AS19: =Append1[[#This Row],[DAY_MCAR]]+Append1[[#This Row],[DAY_MCAR_MC]]+Append1[[#This Row],[DAY_MCAL]]+Append1[[#This Row],[DAY_MCAL_MC]]+Append1[[#This Row],[DAY_CNTY]]+Append1[[#This Row],[DAY_CNTY_MC]]+Append1[[#This Row],[DAY_THRD]]+Append1[[#This Row],[DAY_THRD_MC]]+Append1[[#This Row],[DAY_INDGNT]]+Append1[[#This Row],[DAY_OTH]]+Append1[[#This Row],[DAY_TOT]]+Append1[[#This Row],[DAY_LTC]] -> 19844 | AT19: 989 | AU19: 610 | AV19: 455 | AW19: 2616 | AX19: 0 | AY19: 0 | AZ19: 37 | BA19: 857 | BB19: 0 | BC19: 1267 | BD19: 6831 | BE19: 37307669 | BF19: 19579324 | BG19: 6031893 | BH19: 36021848 | BI19: 0 | BJ19: 0 | BK19: 347976 | BL19: 6458953 | BM19: 0 | BN19: 652463 | BO19: 106400126 | BP19: 6753359 | BQ19: 3947532 | BR19: 1750230 | BS19: 10282475 | BT19: 0 | BU19: 0 | BV19: 329342 | BW19: 5429667 | BX19: 0 | BY19: 1927527 | BZ19: 30420132 | CA19: 480556 | CB19: 33327323 | CC19: 25832341 | CD19: 7110843 | CE19: 46969132 | CF19: 0 | CG19: 0 | CH19: 0 | CI19: 417266 | CJ19: 9966576 | CK19: 0 | CL19: 0 | CM19: 0 | CN19: 0 | CO19: 0 | CP19: 1730417 | CQ19: 125834454 | CR19: 29000055 | CS19: 4813475 | CT19: 0 | CU19: 0 | CV19: 33813530 | CW19: 10733705 | CX19: 26694570 | CY19: 671280 | CZ19: 4148665 | DA19: 0 | DB19: 0 | DC19: 260052 | DD19: 1922044 | DE19: 0 | DF19: 369018 | DG19: 44799334 | DH19: 205527 | DI19: 46112648 | DJ19: 0 | DK19: 123810 | DL19: 0 | DM19: 0 | DN19: 0 | DO19: 0 | DP19: 282613 | DQ19: 7102067 | DR19: 0 | DS19: 0 | DT19: 0 | DU19: 0 | DV19: 0 | DW19: 0 | DX19: 0 | DY19: 0 | DZ19: 0 | EA19: 0 | EB19: 0 | EC19: 0 | ED19: 0
A20: 106010739 | B20: ALTA BATES SUMMIT MEDICAL CENTER - ALTA BATES CAMPUS | C20: 20174 | D20: 43009 | E20: 43100 | F20: Open | G20: Alameda | H20: 5 | I20: 415 | J20: Non Profit Corp. | K20: Comparable | M20: 510-204-4444 | N20: 2450 ASHBY AVENUE | O20: BERKELEY | P20: 94705 | Q20: CHARLES PROSPER | R20: 402 | S20: 402 | T20: 241 | U20: 819 | V20: 221 | W20: 601 | X20: 886 | Y20: 0 | Z20: 0 | AA20: 148 | AB20: 1276 | AC20: 33 | AD20: 13 | AE20: 3997 | AF20: 0 | AG20: 4317 | AH20: 1041 | AI20: 2552 | AJ20: 2913 | AK20: 0 | AL20: 0 | AM20: 1941 | AN20: 5568 | AO20: 135 | AP20: 41 | AQ20: 18508 | AR20: 0 | AS20: =Append1[[#This Row],[DAY_MCAR]]+Append1[[#This Row],[DAY_MCAR_MC]]+Append1[[#This Row],[DAY_MCAL]]+Append1[[#This Row],[DAY_MCAL_MC]]+Append1[[#This Row],[DAY_CNTY]]+Append1[[#This Row],[DAY_CNTY_MC]]+Append1[[#This Row],[DAY_THRD]]+Append1[[#This Row],[DAY_THRD_MC]]+Append1[[#This Row],[DAY_INDGNT]]+Append1[[#This Row],[DAY_OTH]]+Append1[[#This Row],[DAY_TOT]]+Append1[[#This Row],[DAY_LTC]] -> 37016 | AT20: 7599 | AU20: 1908 | AV20: 785 | AW20: 4659 | AX20: 4 | AY20: 0 | AZ20: 250 | BA20: 7742 | BB20: 0 | BC20: 430 | BD20: 23377 | BE20: 63490666 | BF20: 16027829 | BG20: 30587318 | BH20: 47512590 | BI20: 0 | BJ20: 0 | BK20: 24936629 | BL20: 75176664 | BM20: 1837771 | BN20: 558968 | BO20: 260128435 | BP20: 65254269 | BQ20: 18517938 | BR20: 6287452 | BS20: 34692343 | BT20: 61726 | BU20: 0 | BV20: 3251142 | BW20: 67706590 | BX20: 0 | BY20: 2176393 | BZ20: 197947853 | CA20: 3594071 | CB20: 99706178 | CC20: 29308392 | CD20: -66674262 | CE20: 65166599 | CF20: 0 | CG20: 0 | CH20: 0 | CI20: 20810253 | CJ20: 63775552 | CK20: 0 | CL20: 1724634 | CM20: 0 | CN20: 0 | CO20: 0 | CP20: 0 | CQ20: 217411417 | CR20: 813202 | CS20: 0 | CT20: 0 | CU20: 5481154 | CV20: 6294356 | CW20: 29038757 | CX20: 6050577 | CY20: 103549032 | CZ20: 17038334 | DA20: 61726 | DB20: 0 | DC20: 7377518 | DD20: 83730146 | DE20: 113137 | DF20: 0 | DG20: 246959227 | DH20: 2116654 | DI20: 214145635 | DJ20: 0 | DK20: 2373188 | DL20: 0 | DM20: 0 | DN20: 0 | DO20: 0 | DP20: 5731783 | DQ20: 86423187 | DR20: 0 | DS20: 0 | DT20: 0 | DU20: 0 | DV20: 0 | DW20: 0 | DX20: 0 | DY20: 0 | DZ20: 0 | EA20: 0 | EB20: 0 | EC20: 0 | ED20: 0
A21: 106010937 | B21: ALTA BATES SUMMIT MEDICAL CENTER - SUMMIT HAWTHORNE | C21: 20174 | D21: 43009 | E21: 43100 | F21: Open | G21: Alameda | H21: 5 | I21: 417 | J21: Non Profit Corp. | K21: Comparable | M21: 510-655-4000 | N21: 350 HAWTHORNE AVENUE | O21: OAKLAND | P21: 94609 | Q21: CHARLES PROSPER | R21: 354 | S21: 354 | T21: 236 | U21: 1505 | V21: 303 | W21: 225 | X21: 641 | Y21: 0 | Z21: 0 | AA21: 68 | AB21: 475 | AC21: 23 | AD21: 7 | AE21: 3247 | AF21: 0 | AG21: 8509 | AH21: 1807 | AI21: 1734 | AJ21: 3501 | AK21: 0 | AL21: 0 | AM21: 235 | AN21: 2543 | AO21: 75 | AP21: 21 | AQ21: 18425 | AR21: 0 | AS21: =Append1[[#This Row],[DAY_MCAR]]+Append1[[#This Row],[DAY_MCAR_MC]]+Append1[[#This Row],[DAY_MCAL]]+Append1[[#This Row],[DAY_MCAL_MC]]+Append1[[#This Row],[DAY_CNTY]]+Append1[[#This Row],[DAY_CNTY_MC]]+Append1[[#This Row],[DAY_THRD]]+Append1[[#This Row],[DAY_THRD_MC]]+Append1[[#This Row],[DAY_INDGNT]]+Append1[[#This Row],[DAY_OTH]]+Append1[[#This Row],[DAY_TOT]]+Append1[[#This Row],[DAY_LTC]] -> 36850 | AT21: 3261 | AU21: 520 | AV21: 415 | AW21: 4334 | AX21: 0 | AY21: 0 | AZ21: 160 | BA21: 2639 | BB21: 359 | BC21: 282 | BD21: 11970 | BE21: 134971546 | BF21: 29500534 | BG21: 22945388 | BH21: 56108542 | BI21: 0 | BJ21: 0 | BK21: 4477033 | BL21: 46356064 | BM21: 1487244 | BN21: 422893 | BO21: 296269244 | BP21: 39217657 | BQ21: 10089165 | BR21: 6944543 | BS21: 28958085 | BT21: 0 | BU21: 0 | BV21: 1790880 | BW21: 42947602 | BX21: 1953472 | BY21: 1553229 | BZ21: 133454633 | CA21: 3555394 | CB21: 142757295 | CC21: 32555467 | CD21: 18060999 | CE21: 65253776 | CF21: 0 | CG21: 0 | CH21: 0 | CI21: 3594648 | CJ21: 28071121 | CK21: 0 | CL21: 3440716 | CM21: 0 | CN21: 0 | CO21: 0 | CP21: 0 | CQ21: 297289416 | CR21: 0 | CS21: 0 | CT21: 0 | CU21: 0 | CV21: 0 | CW21: 31431908 | CX21: 7034232 | CY21: 11828932 | CZ21: 19812851 | DA21: 0 | DB21: 0 | DC21: 2673265 | DD21: 56212557 | DE21: 3440716 | DF21: 0 | DG21: 132434461 | DH21: -7134396 | DI21: 272388995 | DJ21: 0 | DK21: 5715504 | DL21: 0 | DM21: 0 | DN21: 0 | DO21: 0 | DP21: 13405541 | DQ21: 510783761 | DR21: 0 | DS21: 0 | DT21: 0 | DU21: 0 | DV21: 0 | DW21: 0 | DX21: 0 | DY21: 0 | DZ21: 0 | EA21: 0 | EB21: 0 | EC21: 0 | ED21: 0
A22: 106370749 | B22: ALVARADO PARKWAY INSTITUTE BHS | C22: 20174 | D22: 43009 | E22: 43100 | F22: Open | G22: San Diego | H22: 14 | I22: 1422 | J22: Investor - Corp. | K22: Comparable | M22: 619-465-4411 | N22: 7050 PARKWAY DRIVE | O22: LA MESA | P22: 91942 | Q22: PATRICK ZIEMER | R22: 66 | S22: 66 | T22: 66 | U22: 197 | V22: 52 | W22: 71 | X22: 0 | Y22: 0 | Z22: 0 | AA22: 0 | AB22: 221 | AC22: 0 | AD22: 4 | AE22: 545 | AF22: 0 | AG22: 2541 | AH22: 638 | AI22: 857 | AJ22: 0 | AK22: 0 | AL22: 0 | AM22: 0 | AN22: 1319 | AO22: 0 | AP22: 14 | AQ22: 5369 | AR22: 0 | AS22: =Append1[[#This Row],[DAY_MCAR]]+Append1[[#This Row],[DAY_MCAR_MC]]+Append1[[#This Row],[DAY_MCAL]]+Append1[[#This Row],[DAY_MCAL_MC]]+Append1[[#This Row],[DAY_CNTY]]+Append1[[#This Row],[DAY_CNTY_MC]]+Append1[[#This Row],[DAY_THRD]]+Append1[[#This Row],[DAY_THRD_MC]]+Append1[[#This Row],[DAY_INDGNT]]+Append1[[#This Row],[DAY_OTH]]+Append1[[#This Row],[DAY_TOT]]+Append1[[#This Row],[DAY_LTC]] -> 10738 | AT22: 28822 | AU22: 2371 | AV22: 0 | AW22: 0 | AX22: 0 | AY22: 0 | AZ22: 0 | BA22: 2755 | BB22: 0 | BC22: 112 | BD22: 34060 | BE22: 7585000 | BF22: 1057500 | BG22: 2140000 | BH22: 0 | BI22: 0 | BJ22: 0 | BK22: 0 | BL22: 2625000 | BM22: 0 | BN22: 32500 | BO22: 13440000 | BP22: 6386582 | BQ22: 345629 | BR22: 0 | BS22: 0 | BT22: 0 | BU22: 0 | BV22: 0 | BW22: 231772 | BX22: 0 | BY22: 24544 | BZ22: 6988527 | CA22: 423210 | CB22: 8835457 | CC22: 0 | CD22: 1788907 | CE22: 0 | CF22: 0 | CG22: 0 | CH22: 0 | CI22: 0 | CJ22: 3001677 | CK22: 0 | CL22: 0 | CM22: 0 | CN22: 0 | CO22: 0 | CP22: 0 | CQ22: 14049251 | CR22: 0 | CS22: 0 | CT22: 0 | CU22: 0 | CV22: 0 | CW22: 4712916 | CX22: 1403128 | CY22: 351093 | CZ22: 0 | DA22: 0 | DB22: 0 | DC22: 0 | DD22: -144905 | DE22: 0 | DF22: 57044 | DG22: 6379276 | DH22: 0 | DI22: 6654605 | DJ22: 0 | DK22: 0 | DL22: 0 | DM22: 0 | DN22: 0 | DO22: 0 | DP22: 132724 | DQ22: 1743168 | DR22: 0 | DS22: 0 | DT22: 0 | DU22: 0 | DV22: 0 | DW22: 0 | DX22: 0 | DY22: 0 | DZ22: 0 | EA22: 0 | EB22: 0 | EC22: 0 | ED22: 0
A23: 106194010 | B23: AMERICAN RECOVERY CENTER | C23: 20174 | D23: 43009 | E23: 43100 | F23: Open | G23: Los Angeles | H23: 11 | I23: 917 | J23: Non Profit Corp. | K23: Comparable | M23: 909-865-2336 | N23: 2180 VALLEY BOULEVARD | O23: POMONA | P23: 91768 | Q23: SHIRLEY SUMMERS | R23: 173 | S23: 173 | T23: 173 | U23: 0 | V23: 0 | W23: 0 | X23: 0 | Y23: 486 | Z23: 0 | AA23: 0 | AB23: 0 | AC23: 0 | AD23: 0 | AE23: 486 | AF23: 0 | AG23: 0 | AH23: 0 | AI23: 0 | AJ23: 0 | AK23: 9031 | AL23: 0 | AM23: 0 | AN23: 0 | AO23: 0 | AP23: 0 | AQ23: 9031 | AR23: 0 | AS23: =Append1[[#This Row],[DAY_MCAR]]+Append1[[#This Row],[DAY_MCAR_MC]]+Append1[[#This Row],[DAY_MCAL]]+Append1[[#This Row],[DAY_MCAL_MC]]+Append1[[#This Row],[DAY_CNTY]]+Append1[[#This Row],[DAY_CNTY_MC]]+Append1[[#This Row],[DAY_THRD]]+Append1[[#This Row],[DAY_THRD_MC]]+Append1[[#This Row],[DAY_INDGNT]]+Append1[[#This Row],[DAY_OTH]]+Append1[[#This Row],[DAY_TOT]]+Append1[[#This Row],[DAY_LTC]] -> 18062 | AT23: 0 | AU23: 0 | AV23: 0 | AW23: 0 | AX23: 1536 | AY23: 0 | AZ23: 0 | BA23: 0 | BB23: 0 | BC23: 0 | BD23: 1536 | BE23: 0 | BF23: 0 | BG23: 0 | BH23: 0 | BI23: 1984847 | BJ23: 0 | BK23: 0 | BL23: 0 | BM23: 0 | BN23: 0 | BO23: 1984847 | BP23: 0 | BQ23: 0 | BR23: 0 | BS23: 0 | BT23: 101864 | BU23: 0 | BV23: 0 | BW23: 0 | BX23: 0 | BY23: 0 | BZ23: 101864 | CA23: 0 | CB23: 0 | CC23: 0 | CD23: 0 | CE23: 0 | CF23: 0 | CG23: 0 | CH23: 0 | CI23: 0 | CJ23: 0 | CK23: 0 | CL23: 0 | CM23: 0 | CN23: 0 | CO23: 0 | CP23: 0 | CQ23: 0 | CR23: 0 | CS23: 0 | CT23: 0 | CU23: 0 | CV23: 0 | CW23: 0 | CX23: 0 | CY23: 0 | CZ23: 0 | DA23: 2086711 | DB23: 0 | DC23: 0 | DD23: 0 | DE23: 0 | DF23: 0 | DG23: 2086711 | DH23: 0 | DI23: 1480214 | DJ23: 58213 | DK23: 0 | DL23: 0 | DM23: 0 | DN23: 0 | DO23: 0 | DP23: 0 | DQ23: 2473214 | DR23: 0 | DS23: 0 | DT23: 0 | DU23: 0 | DV23: 0 | DW23: 0 | DX23: 0 | DY23: 0 | DZ23: 0 | EA23: 0 | EB23: 0 | EC23: 0 | ED23: 0
A24: 106301188 | B24: ANAHEIM GLOBAL MEDICAL CENTER | C24: 20174 | D24: 43009 | E24: 43100 | F24: Open | G24: Orange | H24: 13 | I24: 1012 | J24: Investor - Corp. | K24: Comparable | M24: 714-835-3555 | N24: 1025 SOUTH ANAHEIM BOULEVARD. | O24: ANAHEIM | P24: 92805 | Q24: SUZANNE RICHARDS | R24: 188 | S24: 188 | T24: 188 | U24: 138 | V24: 140 | W24: 389 | X24: 174 | Y24: 0 | Z24: 0 | AA24: 160 | AB24: 71 | AC24: 0 | AD24: 42 | AE24: 1114 | AF24: 0 | AG24: 1946 | AH24: 1110 | AI24: 4910 | AJ24: 656 | AK24: 0 | AL24: 0 | AM24: 1514 | AN24: 306 | AO24: 0 | AP24: 186 | AQ24: 10628 | AR24: 0 | AS24: =Append1[[#This Row],[DAY_MCAR]]+Append1[[#This Row],[DAY_MCAR_MC]]+Append1[[#This Row],[DAY_MCAL]]+Append1[[#This Row],[DAY_MCAL_MC]]+Append1[[#This Row],[DAY_CNTY]]+Append1[[#This Row],[DAY_CNTY_MC]]+Append1[[#This Row],[DAY_THRD]]+Append1[[#This Row],[DAY_THRD_MC]]+Append1[[#This Row],[DAY_INDGNT]]+Append1[[#This Row],[DAY_OTH]]+Append1[[#This Row],[DAY_TOT]]+Append1[[#This Row],[DAY_LTC]] -> 21256 | AT24: 609 | AU24: 333 | AV24: 1414 | AW24: 2171 | AX24: 0 | AY24: 0 | AZ24: 960 | BA24: 696 | BB24: 0 | BC24: 629 | BD24: 6812 | BE24: 8886142 | BF24: 10584440 | BG24: 14705310 | BH24: 6376520 | BI24: 0 | BJ24: 0 | BK24: 6184738 | BL24: 3365679 | BM24: 0 | BN24: 1257958 | BO24: 51360787 | BP24: 2527605 | BQ24: 1927798 | BR24: 2732778 | BS24: 5763099 | BT24: 0 | BU24: 0 | BV24: 2872557 | BW24: 2966150 | BX24: 0 | BY24: 1859919 | BZ24: 20649906 | CA24: 2109698 | CB24: 7772904 | CC24: 10691781 | CD24: 13457979 | CE24: 11140687 | CF24: -1799999 | CG24: 0 | CH24: 0 | CI24: 3498060 | CJ24: 2967824 | CK24: 0 | CL24: 0 | CM24: 0 | CN24: 0 | CO24: 0 | CP24: 970320 | CQ24: 50809254 | CR24: 0 | CS24: 0 | CT24: 0 | CU24: 0 | CV24: 0 | CW24: 3640843 | CX24: 1820457 | CY24: 5780108 | CZ24: 998931 | DA24: 0 | DB24: 0 | DC24: 5559235 | DD24: 3364005 | DE24: 0 | DF24: 37860 | DG24: 21201439 | DH24: 47331 | DI24: 18837326 | DJ24: 348579 | DK24: 0 | DL24: 0 | DM24: 0 | DN24: 0 | DO24: 0 | DP24: 293139 | DQ24: 2077974 | DR24: 0 | DS24: 0 | DT24: 0 | DU24: 0 | DV24: 0 | DW24: 0 | DX24: 0 | DY24: 0 | DZ24: 0 | EA24: 0 | EB24: 0 | EC24: 0 | ED24: 0
A25: 106190034 | B25: ANTELOPE VALLEY HOSPITAL | C25: 20174 | D25: 43009 | E25: 43100 | F25: Open | G25: Los Angeles | H25: 11 | I25: 901 | J25: District | K25: Comparable | M25: 661-949-5000 | N25: 1600 WEST AVENUE J | O25: LANCASTER | P25: 93534 | Q25: MICHAEL WALL | R25: 420 | S25: 393 | T25: 249 | U25: 890 | V25: 753 | W25: 730 | X25: 1545 | Y25: 0 | Z25: 0 | AA25: 1179 | AB25: 0 | AC25: 95 | AD25: 35 | AE25: 5227 | AF25: 0 | AG25: 4337 | AH25: 3041 | AI25: 3328 | AJ25: 5407 | AK25: 0 | AL25: 0 | AM25: 3876 | AN25: 0 | AO25: 426 | AP25: 225 | AQ25: 20640 | AR25: 0 | AS25: =Append1[[#This Row],[DAY_MCAR]]+Append1[[#This Row],[DAY_MCAR_MC]]+Append1[[#This Row],[DAY_MCAL]]+Append1[[#This Row],[DAY_MCAL_MC]]+Append1[[#This Row],[DAY_CNTY]]+Append1[[#This Row],[DAY_CNTY_MC]]+Append1[[#This Row],[DAY_THRD]]+Append1[[#This Row],[DAY_THRD_MC]]+Append1[[#This Row],[DAY_INDGNT]]+Append1[[#This Row],[DAY_OTH]]+Append1[[#This Row],[DAY_TOT]]+Append1[[#This Row],[DAY_LTC]] -> 41280 | AT25: 5113 | AU25: 2685 | AV25: 4419 | AW25: 15520 | AX25: 0 | AY25: 0 | AZ25: 7679 | BA25: 0 | BB25: 6834 | BC25: 525 | BD25: 42775 | BE25: 67535230 | BF25: 54642418 | BG25: 41511791 | BH25: 79950347 | BI25: 0 | BJ25: 0 | BK25: 64827058 | BL25: 0 | BM25: 7302602 | BN25: 2928162 | BO25: 318697608 | BP25: 17448903 | BQ25: 23297978 | BR25: 13266843 | BS25: 52424146 | BT25: 0 | BU25: 0 | BV25: 37047079 | BW25: 0 | BX25: 6634072 | BY25: 2634081 | BZ25: 152753102 | CA25: 1682613 | CB25: 68466449 | CC25: 60006389 | CD25: 45441331 | CE25: 117938456 | CF25: -2368418 | CG25: 0 | CH25: 0 | CI25: 79242093 | CJ25: 0 | CK25: 0 | CL25: 2724440 | CM25: 0 | CN25: 0 | CO25: 0 | CP25: 591315 | CQ25: 373724668 | CR25: 0 | CS25: 0 | CT25: 0 | CU25: 0 | CV25: 0 | CW25: 16517684 | CX25: 17934007 | CY25: 11705720 | CZ25: 14436037 | DA25: 0 | DB25: 0 | DC25: 22632044 | DD25: 0 | DE25: 9529621 | DF25: 4970929 | DG25: 97726042 | DH25: 13542251 | DI25: 100721722 | DJ25: 0 | DK25: 110582 | DL25: 0 | DM25: 0 | DN25: 0 | DO25: 0 | DP25: 23463896 | DQ25: 177846360 | DR25: 0 | DS25: 0 | DT25: 0 | DU25: 0 | DV25: 0 | DW25: 0 | DX25: 0 | DY25: 0 | DZ25: 0 | EA25: 0 | EB25: 0 | EC25: 0 | ED25: 0
A26: 106364231 | B26: ARROWHEAD REGIONAL MEDICAL CENTER | C26: 20174 | D26: 43009 | E26: 43100 | F26: Open | G26: San Bernardino | H26: 12 | I26: 1209 | J26: City/County | K26: Comparable | L26: Teaching | M26: 909-580-1000 | N26: 400 N. PEPPER AVENUE | O26: COLTON | P26: 92324 | Q26: WILLIAM GILBERT | R26: 456 | S26: 436 | T26: 368 | U26: 647 | V26: 0 | W26: 2053 | X26: 2275 | Y26: 0 | Z26: 0 | AA26: 237 | AB26: 0 | AC26: 257 | AD26: 6 | AE26: 5475 | AF26: 0 | AG26: 4149 | AH26: 0 | AI26: 12150 | AJ26: 9282 | AK26: 0 | AL26: 0 | AM26: 1425 | AN26: 0 | AO26: 933 | AP26: 10 | AQ26: 27949 | AR26: 0 | AS26: =Append1[[#This Row],[DAY_MCAR]]+Append1[[#This Row],[DAY_MCAR_MC]]+Append1[[#This Row],[DAY_MCAL]]+Append1[[#This Row],[DAY_MCAL_MC]]+Append1[[#This Row],[DAY_CNTY]]+Append1[[#This Row],[DAY_CNTY_MC]]+Append1[[#This Row],[DAY_THRD]]+Append1[[#This Row],[DAY_THRD_MC]]+Append1[[#This Row],[DAY_INDGNT]]+Append1[[#This Row],[DAY_OTH]]+Append1[[#This Row],[DAY_TOT]]+Append1[[#This Row],[DAY_LTC]] -> 55898 | AT26: 12479 | AU26: 0 | AV26: 50092 | AW26: 11642 | AX26: 5 | AY26: 0 | AZ26: 2169 | BA26: 0 | BB26: 5922 | BC26: 208 | BD26: 82517 | BE26: 43287233 | BF26: 0 | BG26: 68295088 | BH26: 84319607 | BI26: 0 | BJ26: 0 | BK26: 16966317 | BL26: 0 | BM26: 9017593 | BN26: 96651 | BO26: 221982489 | BP26: 23330158 | BQ26: 0 | BR26: 48214092 | BS26: 38810302 | BT26: 4560 | BU26: 0 | BV26: 6206527 | BW26: 0 | BX26: 13779706 | BY26: 483989 | BZ26: 130829334 | CA26: 493032 | CB26: 46138377 | CC26: 0 | CD26: 84392576 | CE26: 76725500 | CF26: -3744040 | CG26: 4560 | CH26: 0 | CI26: 15467250 | CJ26: 0 | CK26: 0 | CL26: 19357589 | CM26: 0 | CN26: 0 | CO26: 0 | CP26: 0 | CQ26: 238834844 | CR26: 0 | CS26: 0 | CT26: 0 | CU26: 0 | CV26: 0 | CW26: 20479014 | CX26: 0 | CY26: 35860644 | CZ26: 46404409 | DA26: 0 | DB26: 0 | DC26: 7705594 | DD26: 0 | DE26: 3439710 | DF26: 87608 | DG26: 113976979 | DH26: 14286660 | DI26: 132548751 | DJ26: 0 | DK26: 7734868 | DL26: 0 | DM26: 0 | DN26: 0 | DO26: 0 | DP26: 887651 | DQ26: 347800530 | DR26: 0 | DS26: 0 | DT26: 0 | DU26: 0 | DV26: 0 | DW26: 0 | DX26: 0 | DY26: 0 | DZ26: 0 | EA26: 0 | EB26: 0 | EC26: 0 | ED26: 0
A27: 106400683 | B27: ATASCADERO STATE HOSPITAL | C27: 20174 | D27: 43009 | E27: 43100 | F27: Open | G27: San Luis Obispo | H27: 8 | I27: 801 | J27: State | K27: State Hospitals | M27: 805-468-2000 | N27: 10333 EL CAMINO REAL | O27: ATASCADERO | P27: 93422 | Q27: JON MORALES | R27: 1275 | S27: 1183 | T27: 1183 | U27: 8 | V27: 0 | W27: 0 | X27: 0 | Y27: 0 | Z27: 0 | AA27: 1 | AB27: 0 | AC27: 0 | AD27: 334 | AE27: 343 | AF27: 0 | AG27: 23778 | AH27: 0 | AI27: 0 | AJ27: 0 | AK27: 0 | AL27: 0 | AM27: 4 | AN27: 0 | AO27: 0 | AP27: 78105 | AQ27: 101887 | AR27: 0 | AS27: =Append1[[#This Row],[DAY_MCAR]]+Append1[[#This Row],[DAY_MCAR_MC]]+Append1[[#This Row],[DAY_MCAL]]+Append1[[#This Row],[DAY_MCAL_MC]]+Append1[[#This Row],[DAY_CNTY]]+Append1[[#This Row],[DAY_CNTY_MC]]+Append1[[#This Row],[DAY_THRD]]+Append1[[#This Row],[DAY_THRD_MC]]+Append1[[#This Row],[DAY_INDGNT]]+Append1[[#This Row],[DAY_OTH]]+Append1[[#This Row],[DAY_TOT]]+Append1[[#This Row],[DAY_LTC]] -> 203774 | AT27: 0 | AU27: 0 | AV27: 0 | AW27: 0 | AX27: 0 | AY27: 0 | AZ27: 0 | BA27: 0 | BB27: 0 | BC27: 0 | BD27: 0 | BE27: 12089271 | BF27: 0 | BG27: 0 | BH27: 0 | BI27: 0 | BJ27: 0 | BK27: 1792 | BL27: 0 | BM27: 0 | BN27: 39710260 | BO27: 51801323 | BP27: 0 | BQ27: 0 | BR27: 0 | BS27: 0 | BT27: 0 | BU27: 0 | BV27: 0 | BW27: 0 | BX27: 0 | BY27: 0 | BZ27: 0 | CA27: 0 | CB27: 0 | CC27: 0 | CD27: 0 | CE27: 0 | CF27: 0 | CG27: 0 | CH27: 0 | CI27: 0 | CJ27: 0 | CK27: 0 | CL27: 0 | CM27: 0 | CN27: 0 | CO27: 0 | CP27: 7532 | CQ27: 7532 | CR27: 0 | CS27: 0 | CT27: 0 | CU27: 0 | CV27: 0 | CW27: 12089271 | CX27: 0 | CY27: 0 | CZ27: 0 | DA27: 0 | DB27: 0 | DC27: 1792 | DD27: 0 | DE27: 0 | DF27: 39702728 | DG27: 51793791 | DH27: 0 | DI27: 64212889 | DJ27: 0 | DK27: 12419098 | DL27: 0 | DM27: 0 | DN27: 0 | DO27: 0 | DP27: 0 | DQ27: 0 | DR27: 0 | DS27: 0 | DT27: 0 | DU27: 0 | DV27: 0 | DW27: 0 | DX27: 0 | DY27: 0 | DZ27: 0 | EA27: 0 | EB27: 0 | EC27: 0 | ED27: 0
A28: 106494048 | B28: AURORA BEHAVIORAL HEALTHCARE - SANTA ROSA | C28: 20174 | D28: 43009 | E28: 43100 | F28: Open | G28: Sonoma | H28: 3 | I28: 401 | J28: Investor - Corp. | K28: Comparable | M28: 707-800-7700 | N28: 1287 FULTON ROAD | O28: SANTA ROSA | P28: 95401 | Q28: SUSAN ROSE | R28: 95 | S28: 95 | T28: 64 | U28: 129 | V28: 19 | W28: 242 | X28: 0 | Y28: 87 | Z28: 0 | AA28: 7 | AB28: 209 | AC28: 0 | AD28: 1 | AE28: 694 | AF28: 0 | AG28: 1353 | AH28: 191 | AI28: 2016 | AJ28: 0 | AK28: 722 | AL28: 0 | AM28: 81 | AN28: 1519 | AO28: 0 | AP28: 5 | AQ28: 5887 | AR28: 0 | AS28: =Append1[[#This Row],[DAY_MCAR]]+Append1[[#This Row],[DAY_MCAR_MC]]+Append1[[#This Row],[DAY_MCAL]]+Append1[[#This Row],[DAY_MCAL_MC]]+Append1[[#This Row],[DAY_CNTY]]+Append1[[#This Row],[DAY_CNTY_MC]]+Append1[[#This Row],[DAY_THRD]]+Append1[[#This Row],[DAY_THRD_MC]]+Append1[[#This Row],[DAY_INDGNT]]+Append1[[#This Row],[DAY_OTH]]+Append1[[#This Row],[DAY_TOT]]+Append1[[#This Row],[DAY_LTC]] -> 11774 | AT28: 248 | AU28: 89 | AV28: 0 | AW28: 0 | AX28: 0 | AY28: 0 | AZ28: 0 | BA28: 455 | BB28: 0 | BC28: 0 | BD28: 792 | BE28: 2709025 | BF28: 382400 | BG28: 4033950 | BH28: 0 | BI28: 1445975 | BJ28: 0 | BK28: 162175 | BL28: 3047325 | BM28: 0 | BN28: 10025 | BO28: 11790875 | BP28: 140700 | BQ28: 56700 | BR28: 0 | BS28: 0 | BT28: 0 | BU28: 0 | BV28: 0 | BW28: 270550 | BX28: 0 | BY28: 0 | BZ28: 467950 | CA28: 0 | CB28: 1098326 | CC28: 200957 | CD28: 1679681 | CE28: 0 | CF28: 0 | CG28: 622883 | CH28: 0 | CI28: 66945 | CJ28: 720619 | CK28: 0 | CL28: 0 | CM28: 0 | CN28: 0 | CO28: 0 | CP28: 1317 | CQ28: 4390728 | CR28: 0 | CS28: 0 | CT28: 0 | CU28: 0 | CV28: 0 | CW28: 1751399 | CX28: 238143 | CY28: 2354269 | CZ28: 0 | DA28: 823092 | DB28: 0 | DC28: 95230 | DD28: 2597256 | DE28: 0 | DF28: 8708 | DG28: 7868097 | DH28: 1811 | DI28: 7790631 | DJ28: 967691 | DK28: -1097 | DL28: 0 | DM28: 0 | DN28: 0 | DO28: 0 | DP28: 20927 | DQ28: 180841 | DR28: 0 | DS28: 0 | DT28: 0 | DU28: 0 | DV28: 0 | DW28: 0 | DX28: 0 | DY28: 0 | DZ28: 0 | EA28: 0 | EB28: 0 | EC28: 0 | ED28: 0
